==========================================
real base lr:  0.1
==========================================
Compose(
    RandomResizedCrop(size=(224, 224), scale=(0.08, 1.0), ratio=(0.75, 1.3333), interpolation=bilinear), antialias=None)
    RandomHorizontalFlip(p=0.5)
    ToTensor()
    Normalize(mean=(0.485, 0.456, 0.406), std=(0.229, 0.224, 0.225))
)
use raw ImageNet data
local rank 3 / global rank 3 successfully build train dataset
use raw ImageNet data
local rank 3 / global rank 3 successfully build val dataset
=================== Building the vanila RepVGG ===================
RepVGG Block, identity =  None
RepVGG Block, identity =  None
RepVGG Block, identity =  Identity()
RepVGG Block, identity =  None
RepVGG Block, identity =  Identity()
RepVGG Block, identity =  Identity()
RepVGG Block, identity =  Identity()
RepVGG Block, identity =  None
RepVGG Block, identity =  Identity()
RepVGG Block, identity =  Identity()
RepVGG Block, identity =  Identity()
RepVGG Block, identity =  Identity()
RepVGG Block, identity =  Identity()
RepVGG Block, identity =  Identity()
RepVGG Block, identity =  Identity()
RepVGG Block, identity =  Identity()
RepVGG Block, identity =  Identity()
RepVGG Block, identity =  Identity()
RepVGG Block, identity =  Identity()
RepVGG Block, identity =  Identity()
RepVGG Block, identity =  Identity()
RepVGG Block, identity =  None
/opt/conda/lib/python3.8/site-packages/torchvision/transforms/transforms.py:329: UserWarning: Argument 'interpolation' of type int is deprecated since 0.13 and will be removed in 0.15. Please use InterpolationMode enum.
  warnings.warn(
/opt/conda/lib/python3.8/site-packages/torch/nn/parallel/scatter_gather.py:9: UserWarning: is_namedtuple is deprecated, please use the python checks instead
  warnings.warn("is_namedtuple is deprecated, please use the python checks instead")
Error in sys.excepthook:
Traceback (most recent call last):
  File "/opt/conda/lib/python3.8/site-packages/wandb/sdk/lib/exit_hooks.py", line 44, in exc_handler
    self.exit_code = 1
KeyboardInterrupt
Original exception was:
Traceback (most recent call last):
  File "main.py", line 424, in <module>
    main(config)
  File "main.py", line 160, in main
    train_one_epoch(config, model, criterion, data_loader_train, optimizer, epoch, mixup_fn, lr_scheduler, model_ema=model_ema)
  File "main.py", line 208, in train_one_epoch
    for idx, (samples, targets) in enumerate(data_loader):
  File "/opt/conda/lib/python3.8/site-packages/torch/utils/data/dataloader.py", line 668, in __next__
    data = self._next_data()
  File "/opt/conda/lib/python3.8/site-packages/torch/utils/data/dataloader.py", line 1344, in _next_data
    idx, data = self._get_data()
  File "/opt/conda/lib/python3.8/site-packages/torch/utils/data/dataloader.py", line 1300, in _get_data
    success, data = self._try_get_data()
  File "/opt/conda/lib/python3.8/site-packages/torch/utils/data/dataloader.py", line 1148, in _try_get_data
    data = self._data_queue.get(timeout=timeout)
  File "/opt/conda/lib/python3.8/queue.py", line 179, in get
    self.not_empty.wait(remaining)
  File "/opt/conda/lib/python3.8/threading.py", line 306, in wait
    gotit = waiter.acquire(True, timeout)
KeyboardInterrupt